Workbook

Sheet Rules
A1: STOCK ACTION SPEC — two new columns: "Company Type" and "Action"
B2: Purpose: score each stock from one day's screener row. Everything below is implemented as live formulas on the "Scored Data" sheet, with every threshold on the "Parameters" sheet. Column header comments on Scored Data explain each helper column. Output values for Action: Sell Immediately | Avoid | Hold | Buy with Risk | Buy | Strong Buy. A "Flags" column explains any override that changed the result.
A3: STEP 1 — Company Type (ETF / Established / Early)
B4: 1a ETF | C4: Portfolios contains "ETF", OR both Quality and Forward P/E are blank → "ETF". ETFs get technical scoring only.
B5: 1b Establishment score (0–7) | C5: Market Cap ≥ mc_big → +2 (≥ mc_mid → +1). Net Income TTM > 0 AND Profit Margin ≥ pm_est → +2 (Net Income > 0 alone → +1). FCF TTM > 0 AND FCF Margin ≥ fm_est → +1. 0 < Forward P/E ≤ pe_max → +1. Quality ≥ q_est → +1.
B6: 1c Classification | C6: Market Cap ≥ mc_override → "Established" (size override). Else score ≥ est_min → "Established", else "Early". Early = valued on future growth / not yet consistently profitable (SG, JOBY, CAVA, CRWV, SNOW, CRWD...). Established = large, profitable, sanely valued (AAPL, JPM, MU...).
A7: STEP 2 — Technical Score (all types, −10 … +10)
B8: T1 MA Cross | C8: Golden* → +2, Death* → −2, blank → 0 (LEFT() match, so "Golden (8d)" counts as Golden).
B9: T2 vs 200D MA % | C9: > v200_hi → +2; > 0 → +1; ≥ v200_lo → −1; < v200_lo → −2.
B10: T3 vs 50D MA % | C10: v50_lo ≤ x ≤ v50_hi → +1 (pullback/base). x > v50_ext (extended) or x < v50_wk (weak) → −1.
B11: T4 RSI | C11: rsi_lo ≤ RSI ≤ rsi_hi → +1. RSI > rsi_ob or RSI < rsi_os → −1.
B12: T5 Momentum Delta (2w) | C12: > md_up → +1; < md_dn → −1.
B13: T6 Momentum score | C13: ≥ mo_hi → +1; ≤ mo_lo → −1.
B14: T7 Volume confirmation | C14: Vol Trend % > vt_hi: if 1M % < 0 → −1 (distribution), if 1M % > 0 → +1 (accumulation).
B15: T8 % from 52W High | C15: > fh_near → +1; < fh_deep → −1.
A16: STEP 3 — Fundamental Score (rule set depends on Company Type)
B17: Established (FE1–FE6) | C17: Quality ≥ q_hi → +2 / ≥ q_mid → +1 / ≤ q_low → −1. Earnings Growth > eg_est → +1, < 0 → −1. Revenue Growth > rg_est → +1, < 0 → −1. 0 < PEG ≤ peg_ok → +1, PEG > peg_bad → −1. FCF Margin > fm_hi → +1, < 0 → −1. Net Cash > 0 → +1.
B18: Early (EA1–EA6) | C18: Revenue Growth > rg_e2 → +2 / > rg_e1 → +1 / < rg_e_lo → −1 / < 0 → −2. Gross Margin > gm_hi → +1, < gm_lo → −1. FCF TTM > 0 → +1, else FCF Margin < fm_neg → −1. Net Income TTM > 0 → +1. Short % Float > sf_vhi → −2, > sf_hi → −1. Quality ≥ q_e_hi → +1, ≤ q_e_lo → −1. (Early companies are judged on growth, gross margin and cash burn — not on P/E, PEG or earnings growth, which are meaningless for them.)
B19: ETF | C19: Fund Score = 0.
A20: STEP 4 — Composite and base tier
B21: Composite | C21: Established: Tech + Fund. Early: Tech + early_fund_wt × Fund (technicals carry more weight because Early fundamentals are noisy). ETF: Tech.
B22: Established tiers | C22: ≥ est_sb Strong Buy | ≥ est_b Buy | ≥ est_bwr Buy with Risk | ≥ est_h Hold | ≥ est_av Avoid | else Sell Immediately.
B23: Early tiers | C23: ≥ early_b Buy | ≥ early_bwr Buy with Risk | ≥ early_h Hold | ≥ early_av Avoid | else Sell Immediately. Early can never be Strong Buy.
B24: ETF tiers | C24: ≥ etf_sb Strong Buy | ≥ etf_b Buy | ≥ etf_bwr Buy with Risk | ≥ etf_h Hold | ≥ etf_av Avoid | else Sell Immediately.
A25: STEP 5 — Overrides (the loss-avoidance layer; ranks 1=Sell Immediately … 6=Strong Buy)
B26: OV Hard Sell (→ rank 1, always wins) | C26: Established: MA Cross = Death AND vs 200D < hs_est_v200 AND (1M % < hs_est_m1 OR 3M % < hs_est_m3). Early: MA Cross = Death AND vs 200D < hs_early_v200 AND 1M % < hs_early_m1 (Early gets a shorter leash).
B27: OV Below 200D (cap) | C27: vs 200D < 0 and no hard sell: Established capped at Hold (rank below200_cap_est); Early capped at Avoid (rank below200_cap_early). A stock under its 200D is never a buy.
B28: OV Insufficient history (cap Hold) | C28: History Days < hist_min.
B29: OV Extended (cap Hold) | C29: 1M % > ext_m1 OR vs 50D > ext_v50 OR RSI > ext_rsi → don't chase; wait for a pullback.
B30: OV Earnings (cap Hold) | C30: 0 ≤ Days to Earnings ≤ earn_days → no new entries into an earnings print.
B31: Final | C31: Final Rank = 1 if hard sell, else MIN(Base Rank, all active caps). Action = tier label for Final Rank. Flags lists the overrides that fired.
A32: NOTES FOR IMPLEMENTATION
B33: • Blank numeric cells must be treated as "no information" (0 points), never as 0 or as a large number — every formula wraps comparisons in ISNUMBER(). • MA Cross is matched on prefix ("Golden", "Death"). • Days to Earnings that are negative mean a stale date and are ignored. • The Parameters sheet values are starting points chosen so today's file gives a sensible spread; they are meant to be tuned by backtesting against the Fwd +1M/+3M/+6M % columns in the historical files. • Type is recomputed daily, so a company can migrate from Early to Established (e.g. once it turns profitable).

Sheet Parameters
A1: Parameter | B1: Value | C1: Meaning | E1: Tier rank | F1: Action label
A2: COMPANY TYPE (Established vs Early) | E2: 1 | F2: Sell Immediately
A3: mc_big | B3: 100000000000 | C3: Market Cap >= this → +2 establishment pts | E3: 2 | F3: Avoid
A4: mc_mid | B4: 20000000000 | C4: Market Cap >= this (but < mc_big) → +1 | E4: 3 | F4: Hold
A5: pm_est | B5: 5 | C5: Profit Margin % >= this (with positive Net Income) → +2; positive Net Income alone → +1 | E5: 4 | F5: Buy with Risk
A6: fm_est | B6: 5 | C6: FCF Margin % >= this (with positive FCF) → +1 | E6: 5 | F6: Buy
A7: pe_max | B7: 40 | C7: Forward P/E between 0 and this → +1 | E7: 6 | F7: Strong Buy
A8: q_est | B8: 7 | C8: Quality >= this → +1
A9: est_min | B9: 5 | C9: Establishment score >= this → Established, else Early (max score = 7) | E9: Blue/yellow cells are the editable thresholds. Every formula on the Scored Data sheet references these cells, so changing a value here re-scores every stock.
A10: mc_override | B10: 200000000000 | C10: Market Cap >= this → always Established regardless of score (e.g. TSLA)
A11: TECHNICAL SCORE (all types, range -10..+10)
A12: v200_hi | B12: 10 | C12: vs 200D MA % > this → +2; > 0 → +1
A13: v200_lo | B13: -10 | C13: vs 200D MA % < 0 and >= this → -1; < this → -2
A14: v50_lo | B14: -3 | C14: vs 50D MA % between v50_lo and v50_hi → +1 (healthy pullback / base)
A15: v50_hi | B15: 8
A16: v50_ext | B16: 15 | C16: vs 50D MA % > this → -1 (extended)
A17: v50_wk | B17: -8 | C17: vs 50D MA % < this → -1 (weak)
A18: rsi_lo | B18: 45 | C18: RSI between rsi_lo and rsi_hi → +1
A19: rsi_hi | B19: 65
A20: rsi_ob | B20: 72 | C20: RSI > this → -1 (overbought)
A21: rsi_os | B21: 35 | C21: RSI < this → -1 (oversold / broken)
A22: md_up | B22: 3 | C22: Momentum Delta (2 weeks) > this → +1
A23: md_dn | B23: -5 | C23: Momentum Delta (2 weeks) < this → -1
A24: mo_hi | B24: 7 | C24: Momentum score >= this → +1
A25: mo_lo | B25: 3 | C25: Momentum score <= this → -1
A26: vt_hi | B26: 10 | C26: Vol Trend % > this: +1 if 1M % > 0 (accumulation), -1 if 1M % < 0 (distribution)
A27: fh_near | B27: -10 | C27: % from 52W High > this → +1
A28: fh_deep | B28: -30 | C28: % from 52W High < this → -1
A29: FUNDAMENTAL SCORE – ESTABLISHED (range -5..+7)
A30: q_hi | B30: 8 | C30: Quality >= this → +2
A31: q_mid | B31: 6 | C31: Quality >= this → +1
A32: q_low | B32: 4 | C32: Quality <= this → -1
A33: eg_est | B33: 15 | C33: Earnings Growth % > this → +1; < 0 → -1
A34: rg_est | B34: 10 | C34: Revenue Growth % > this → +1; < 0 → -1
A35: peg_ok | B35: 1.5 | C35: PEG between 0 and this → +1
A36: peg_bad | B36: 3 | C36: PEG > this → -1 (negative PEG = 0 pts)
A37: fm_hi | B37: 10 | C37: FCF Margin % > this → +1; < 0 → -1
A38: FUNDAMENTAL SCORE – EARLY (range -7..+6)
A39: rg_e2 | B39: 30 | C39: Revenue Growth % > this → +2
A40: rg_e1 | B40: 15 | C40: Revenue Growth % > this → +1
...

Sheet Scored Data
A1: Symbol | B1: Overall | C1: Momentum | D1: Past Momentum (2 weeks) | E1: Momentum Delta (2 weeks) | F1: Quality | G1: Name | H1: Portfolios | I1: Price | J1: Currency | K1: Sector | L1: Market Cap | M1: Last Earnings | N1: Last Surprise % | O1: Next Earnings | P1: Next Est? | Q1: Today % | R1: Yesterday % | S1: 1W % | T1: 2W % | U1: 1M % | V1: 3M % | W1: 6M % | X1: 1Y % | Y1: Fwd +1M % | Z1: Fwd +3M % | AA1: Fwd +6M % | AB1: Fwd Since % | AC1: RS vs S&P % | AD1: % from 52W High | AE1: RSI | AF1: vs 50D MA % | AG1: vs 200D MA % | AH1: MA Cross | AI1: MACD Hist | AJ1: Vol Trend % | AK1: Earnings Growth % | AL1: Revenue Growth % | AM1: Profit Margin % | AN1: ROE % | AO1: Forward P/E | AP1: PEG | AQ1: Short % Float | AR1: History Days | AS1: Latest Data | AT1: Revenue TTM | AU1: Gross Profit TTM | AV1: Gross Margin % | AW1: Net Income TTM | AX1: FCF TTM | AY1: FCF Margin % | AZ1: Net Cash | BA1: % from 52W Low | BB1: 52W Range Pos % | BC1: Days to Earnings | BD1: Is ETF | BE1: Est Score | BF1: Company Type | BG1: T1 MA Cross | BH1: T2 vs 200D | BI1: T3 vs 50D | BJ1: T4 RSI | BK1: T5 Mom Delta | BL1: T6 Momentum | BM1: T7 Volume | BN1: T8 52W High | BO1: Tech Score | BP1: FE1 Quality | BQ1: FE2 Earn Growth | BR1: FE3 Rev Growth | BS1: FE4 PEG | BT1: FE5 FCF Margin | BU1: FE6 Net Cash | BV1: EA1 Rev Growth | BW1: EA2 Gross Margin | BX1: EA3 FCF | BY1: EA4 Profitable | BZ1: EA5 Short Float | CA1: EA6 Quality | CB1: Fund Score | CC1: Composite | CD1: Base Rank | CE1: OV Hist | CF1: OV Hard Sell | CG1: OV Below 200D | CH1: OV Extended | CI1: OV Earnings | CJ1: Final Rank | CK1: Action | CL1: Flags
A2: SKHY | B2: 10 | F2: 10 | G2: SK hynix Inc. American Depositary Receipt | H2: Memory | I2: 190.67 | J2: USD | K2: Technology | L2: 1409984769993 | M2: 46232 | N2: 86.04 | O2: 46323 | P2: estimated | Q2: -4.01 | R2: 7.05 | S2: 15.57 | T2: 20.66 | U2: 34.61 | AD2: -4.6 | AE2: 62.55 | AI2: 3.69 | AJ2: -0.65 | AK2: 1240.8 | AL2: 256.8 | AM2: 85.62 | AN2: 354.06 | AO2: 5.56 | AP2: 0.01 | AQ2: 0.4 | AR2: 44 | AS2: 46275 | AT2: 140924537488 | AU2: 107480027316 | AV2: 76.27 | AW2: 120657742722 | AX2: 41545003272 | AY2: 29.48 | AZ2: 26468371611 | BA2: 52.78 | BB2: 87.74 | BC2: =IF(AND(ISNUMBER(O2),ISNUMBER(AS2)),O2-AS2,"") -> 48 | BD2: =IF(OR(ISNUMBER(SEARCH("ETF",H2)),AND(F2="",AO2="")),1,0) -> 0 | BE2: =IF(ISNUMBER(L2),IF(L2>=Parameters!$B$3,2,IF(L2>=Parameters!$B$4,1,0)),0)+IF(ISNUMBER(AW2),IF(AW2>0,IF(AND(ISNUMBER(AM2),AM2>=Parameters!$B$5),2,1),0),0)+IF(ISNUMBER(AX2),IF(AND(AX2>0,ISNUMBER(AY2),AY2>=Parameters!$B$6),1,0),0)+IF(ISNUMBER(AO2),IF(AND(AO2>0,AO2<=Parameters!$B$7),1,0),0)+IF(ISNUMBER(F2),IF(F2>=Parameters!$B$8,1,0),0) -> 7 | BF2: =IF(BD2=1,"ETF",IF(OR(AND(ISNUMBER(L2),L2>=Parameters!$B$10),BE2>=Parameters!$B$9),"Established","Early")) -> Established | BG2: =IF(LEFT(AH2,6)="Golden",2,IF(LEFT(AH2,5)="Death",-2,0)) -> 0 | BH2: =IF(ISNUMBER(AG2),IF(AG2>Parameters!$B$12,2,IF(AG2>0,1,IF(AG2>=Parameters!$B$13,-1,-2))),0) -> 0 | BI2: =IF(ISNUMBER(AF2),IF(AND(AF2>=Parameters!$B$14,AF2<=Parameters!$B$15),1,IF(OR(AF2>Parameters!$B$16,AF2<Parameters!$B$17),-1,0)),0) -> 0 | BJ2: =IF(ISNUMBER(AE2),IF(AND(AE2>=Parameters!$B$18,AE2<=Parameters!$B$19),1,IF(OR(AE2>Parameters!$B$20,AE2<Parameters!$B$21),-1,0)),0) -> 1 | BK2: =IF(ISNUMBER(E2),IF(E2>Parameters!$B$22,1,IF(E2<Parameters!$B$23,-1,0)),0) -> 0 | BL2: =IF(ISNUMBER(C2),IF(C2>=Parameters!$B$24,1,IF(C2<=Parameters!$B$25,-1,0)),0) -> 0 | BM2: =IF(ISNUMBER(AJ2),IF(AND(AJ2>Parameters!$B$26,ISNUMBER(U2)),IF(U2<0,-1,1),0),0) -> 0 | BN2: =IF(ISNUMBER(AD2),IF(AD2>Parameters!$B$27,1,IF(AD2<Parameters!$B$28,-1,0)),0) -> 1 | BO2: =BG2+BH2+BI2+BJ2+BK2+BL2+BM2+BN2 -> 2 | BP2: =IF(ISNUMBER(F2),IF(F2>=Parameters!$B$30,2,IF(F2>=Parameters!$B$31,1,IF(F2<=Parameters!$B$32,-1,0))),0) -> 2 | BQ2: =IF(ISNUMBER(AK2),IF(AK2>Parameters!$B$33,1,IF(AK2<0,-1,0)),0) -> 1 | BR2: =IF(ISNUMBER(AL2),IF(AL2>Parameters!$B$34,1,IF(AL2<0,-1,0)),0) -> 1 | BS2: =IF(ISNUMBER(AP2),IF(AND(AP2>0,AP2<=Parameters!$B$35),1,IF(AP2>Parameters!$B$36,-1,0)),0) -> 1 | BT2: =IF(ISNUMBER(AY2),IF(AY2>Parameters!$B$37,1,IF(AY2<0,-1,0)),0) -> 1 | BU2: =IF(ISNUMBER(AZ2),IF(AZ2>0,1,0),0) -> 1 | BV2: =IF(ISNUMBER(AL2),IF(AL2>Parameters!$B$39,2,IF(AL2>Parameters!$B$40,1,IF(AL2<0,-2,IF(AL2<Parameters!$B$41,-1,0)))),0) -> 2 | BW2: =IF(ISNUMBER(AV2),IF(AV2>Parameters!$B$42,1,IF(AV2<Parameters!$B$43,-1,0)),0) -> 1 | BX2: =IF(AND(ISNUMBER(AX2),AX2>0),1,IF(AND(ISNUMBER(AY2),AY2<Parameters!$B$44),-1,0)) -> 1 | BY2: =IF(ISNUMBER(AW2),IF(AW2>0,1,0),0) -> 1 | BZ2: =IF(ISNUMBER(AQ2),IF(AQ2>Parameters!$B$46,-2,IF(AQ2>Parameters!$B$45,-1,0)),0) -> 0 | CA2: =IF(ISNUMBER(F2),IF(F2>=Parameters!$B$47,1,IF(F2<=Parameters!$B$48,-1,0)),0) -> 1 | CB2: =IF(BF2="Established",BP2+BQ2+BR2+BS2+BT2+BU2,IF(BF2="Early",BV2+BW2+BX2+BY2+BZ2+CA2,0)) -> 7 | CC2: =IF(BF2="Established",BO2+CB2,IF(BF2="Early",BO2+Parameters!$B$50*CB2,BO2)) -> 9 | CD2: =IF(BF2="Established",IF(CC2>=Parameters!$B$51,6,IF(CC2>=Parameters!$B$52,5,IF(CC2>=Parameters!$B$53,4,IF(CC2>=Parameters!$B$54,3,IF(CC2>=Parameters!$B$55,2,1))))),IF(BF2="Early",IF(CC2>=Parameters!$B$56,5,IF(CC2>=Parameters!$B$57,4,IF(CC2>=Parameters!$B$58,3,IF(CC2>=Parameters!$B$59,2,1)))),IF(CC2>=Parameters!$B$60,6,IF(CC2>=Parameters!$B$61,5,IF(CC2>=Parameters!$B$62,4,IF(CC2>=Parameters!$B$63,3,IF(CC2>=Parameters!$B$64,2,1))))))) -> 5 | CE2: =IF(AND(ISNUMBER(AR2),AR2<Parameters!$B$66),1,0) -> 1 | CF2: =IF(AND(LEFT(AH2,5)="Death",ISNUMBER(AG2)),IF(BF2="Early",IF(AND(AG2<Parameters!$B$70,ISNUMBER(U2),U2<Parameters!$B$71),1,0),IF(AND(AG2<Parameters!$B$67,OR(AND(ISNUMBER(U2),U2<Parameters!$B$68),AND(ISNUMBER(V2),V2<Parameters!$B$69))),1,0)),0) -> 0 | CG2: =IF(AND(ISNUMBER(AG2),AG2<0),1,0) -> 0 | CH2: =IF(OR(AND(ISNUMBER(U2),U2>Parameters!$B$74),AND(ISNUMBER(AF2),AF2>Parameters!$B$75),AND(ISNUMBER(AE2),AE2>Parameters!$B$76)),1,0) -> 1 | CI2: =IF(AND(ISNUMBER(BC2),BC2>=0,BC2<=Parameters!$B$77),1,0) -> 0 | CJ2: =IF(CF2=1,1,MIN(CD2,IF(CE2=1,3,6),IF(CG2=1,IF(BF2="Early",Parameters!$B$73,Parameters!$B$72),6),IF(CH2=1,3,6),IF(CI2=1,3,6))) -> 3 | CK2: =INDEX(Parameters!$F$2:$F$7,CJ2) -> Hold | CL2: =IF(CF2=1,"Hard sell: breakdown; ","")&IF(CE2=1,"Insufficient history; ","")&IF(AND(CF2=0,CG2=1),"Below 200D; ","")&IF(CH2=1,"Extended - wait for pullback; ","")&IF(CI2=1,"Earnings within "&Parameters!$B$77&"d; ","") -> Insufficient history; Extended - wait for pullback;
A3: MU | B3: 8 | C3: 7 | D3: 67.2 | E3: 3.7 | F3: 10 | G3: Micron Technology, Inc. | H3: Chips; Memory | I3: 979.59 | J3: USD | K3: Technology | L3: 1160756421391 | M3: 46197 | N3: 21.36 | O3: 46288 | P3: estimated | Q3: -4.69 | R3: 2.75 | S3: 2.46 | T3: 4.39 | U3: 12.79 | V3: 9.83 | W3: 133.97 | X3: 624.33 | AC3: 5.19 | AD3: -21.95 | AE3: 53.57 | AF3: 5.36 | AG3: 58.45 | AH3: Golden | AI3: 6.23 | AJ3: -13.69 | AK3: 1398.3 | AL3: 345.7 | AM3: 55.91 | AN3: 66.64 | AO3: 6.62 | AP3: 0.02 | AQ3: 2.67 | AR3: 300 | AS3: 46275 | AT3: 90273996800 | AU3: 65510998016 | AV3: 72.57 | AW3: 50468999168 | AX3: 7639499776 | AY3: 8.46 | AZ3: 19646000640 | BA3: 608.1 | BB3: 75.34 | BC3: =IF(AND(ISNUMBER(O3),ISNUMBER(AS3)),O3-AS3,"") -> 13 | BD3: =IF(OR(ISNUMBER(SEARCH("ETF",H3)),AND(F3="",AO3="")),1,0) -> 0 | BE3: =IF(ISNUMBER(L3),IF(L3>=Parameters!$B$3,2,IF(L3>=Parameters!$B$4,1,0)),0)+IF(ISNUMBER(AW3),IF(AW3>0,IF(AND(ISNUMBER(AM3),AM3>=Parameters!$B$5),2,1),0),0)+IF(ISNUMBER(AX3),IF(AND(AX3>0,ISNUMBER(AY3),AY3>=Parameters!$B$6),1,0),0)+IF(ISNUMBER(AO3),IF(AND(AO3>0,AO3<=Parameters!$B$7),1,0),0)+IF(ISNUMBER(F3),IF(F3>=Parameters!$B$8,1,0),0) -> 7 | BF3: =IF(BD3=1,"ETF",IF(OR(AND(ISNUMBER(L3),L3>=Parameters!$B$10),BE3>=Parameters!$B$9),"Established","Early")) -> Established | BG3: =IF(LEFT(AH3,6)="Golden",2,IF(LEFT(AH3,5)="Death",-2,0)) -> 2 | BH3: =IF(ISNUMBER(AG3),IF(AG3>Parameters!$B$12,2,IF(AG3>0,1,IF(AG3>=Parameters!$B$13,-1,-2))),0) -> 2 | BI3: =IF(ISNUMBER(AF3),IF(AND(AF3>=Parameters!$B$14,AF3<=Parameters!$B$15),1,IF(OR(AF3>Parameters!$B$16,AF3<Parameters!$B$17),-1,0)),0) -> 1 | BJ3: =IF(ISNUMBER(AE3),IF(AND(AE3>=Parameters!$B$18,AE3<=Parameters!$B$19),1,IF(OR(AE3>Parameters!$B$20,AE3<Parameters!$B$21),-1,0)),0) -> 1 | BK3: =IF(ISNUMBER(E3),IF(E3>Parameters!$B$22,1,IF(E3<Parameters!$B$23,-1,0)),0) -> 1 | BL3: =IF(ISNUMBER(C3),IF(C3>=Parameters!$B$24,1,IF(C3<=Parameters!$B$25,-1,0)),0) -> 1 | BM3: =IF(ISNUMBER(AJ3),IF(AND(AJ3>Parameters!$B$26,ISNUMBER(U3)),IF(U3<0,-1,1),0),0) -> 0 | BN3: =IF(ISNUMBER(AD3),IF(AD3>Parameters!$B$27,1,IF(AD3<Parameters!$B$28,-1,0)),0) -> 0 | BO3: =BG3+BH3+BI3+BJ3+BK3+BL3+BM3+BN3 -> 8 | BP3: =IF(ISNUMBER(F3),IF(F3>=Parameters!$B$30,2,IF(F3>=Parameters!$B$31,1,IF(F3<=Parameters!$B$32,-1,0))),0) -> 2 | BQ3: =IF(ISNUMBER(AK3),IF(AK3>Parameters!$B$33,1,IF(AK3<0,-1,0)),0) -> 1 | BR3: =IF(ISNUMBER(AL3),IF(AL3>Parameters!$B$34,1,IF(AL3<0,-1,0)),0) -> 1 | BS3: =IF(ISNUMBER(AP3),IF(AND(AP3>0,AP3<=Parameters!$B$35),1,IF(AP3>Parameters!$B$36,-1,0)),0) -> 1 | BT3: =IF(ISNUMBER(AY3),IF(AY3>Parameters!$B$37,1,IF(AY3<0,-1,0)),0) -> 0 | BU3: =IF(ISNUMBER(AZ3),IF(AZ3>0,1,0),0) -> 1 | BV3: =IF(ISNUMBER(AL3),IF(AL3>Parameters!$B$39,2,IF(AL3>Parameters!$B$40,1,IF(AL3<0,-2,IF(AL3<Parameters!$B$41,-1,0)))),0) -> 2 | BW3: =IF(ISNUMBER(AV3),IF(AV3>Parameters!$B$42,1,IF(AV3<Parameters!$B$43,-1,0)),0) -> 1 | BX3: =IF(AND(ISNUMBER(AX3),AX3>0),1,IF(AND(ISNUMBER(AY3),AY3<Parameters!$B$44),-1,0)) -> 1 | BY3: =IF(ISNUMBER(AW3),IF(AW3>0,1,0),0) -> 1 | BZ3: =IF(ISNUMBER(AQ3),IF(AQ3>Parameters!$B$46,-2,IF(AQ3>Parameters!$B$45,-1,0)),0) -> 0 | CA3: =IF(ISNUMBER(F3),IF(F3>=Parameters!$B$47,1,IF(F3<=Parameters!$B$48,-1,0)),0) -> 1 | CB3: =IF(BF3="Established",BP3+BQ3+BR3+BS3+BT3+BU3,IF(BF3="Early",BV3+BW3+BX3+BY3+BZ3+CA3,0)) -> 6 | CC3: =IF(BF3="Established",BO3+CB3,IF(BF3="Early",BO3+Parameters!$B$50*CB3,BO3)) -> 14 | CD3: =IF(BF3="Established",IF(CC3>=Parameters!$B$51,6,IF(CC3>=Parameters!$B$52,5,IF(CC3>=Parameters!$B$53,4,IF(CC3>=Parameters!$B$54,3,IF(CC3>=Parameters!$B$55,2,1))))),IF(BF3="Early",IF(CC3>=Parameters!$B$56,5,IF(CC3>=Parameters!$B$57,4,IF(CC3>=Parameters!$B$58,3,IF(CC3>=Parameters!$B$59,2,1)))),IF(CC3>=Parameters!$B$60,6,IF(CC3>=Parameters!$B$61,5,IF(CC3>=Parameters!$B$62,4,IF(CC3>=Parameters!$B$63,3,IF(CC3>=Parameters!$B$64,2,1))))))) -> 6 | CE3: =IF(AND(ISNUMBER(AR3),AR3<Parameters!$B$66),1,0) -> 0 | CF3: =IF(AND(LEFT(AH3,5)="Death",ISNUMBER(AG3)),IF(BF3="Early",IF(AND(AG3<Parameters!$B$70,ISNUMBER(U3),U3<Parameters!$B$71),1,0),IF(AND(AG3<Parameters!$B$67,OR(AND(ISNUMBER(U3),U3<Parameters!$B$68),AND(ISNUMBER(V3),V3<Parameters!$B$69))),1,0)),0) -> 0 | CG3: =IF(AND(ISNUMBER(AG3),AG3<0),1,0) -> 0 | CH3: =IF(OR(AND(ISNUMBER(U3),U3>Parameters!$B$74),AND(ISNUMBER(AF3),AF3>Parameters!$B$75),AND(ISNUMBER(AE3),AE3>Parameters!$B$76)),1,0) -> 0 | CI3: =IF(AND(ISNUMBER(BC3),BC3>=0,BC3<=Parameters!$B$77),1,0) -> 0 | CJ3: =IF(CF3=1,1,MIN(CD3,IF(CE3=1,3,6),IF(CG3=1,IF(BF3="Early",Parameters!$B$73,Parameters!$B$72),6),IF(CH3=1,3,6),IF(CI3=1,3,6))) -> 6 | CK3: =INDEX(Parameters!$F$2:$F$7,CJ3) -> Strong Buy | CL3: =IF(CF3=1,"Hard sell: breakdown; ","")&IF(CE3=1,"Insufficient history; ","")&IF(AND(CF3=0,CG3=1),"Below 200D; ","")&IF(CH3=1,"Extended - wait for pullback; ","")&IF(CI3=1,"Earnings within "&Parameters!$B$77&"d; ","")
A4: JPM | B4: 8 | C4: 8 | D4: 68.5 | E4: 4.2 | F4: 10 | G4: JPMorgan Chase & Co. | H4: Fin | I4: 352.78 | J4: USD | K4: Financial Services | L4: 942885198646 | M4: 46226 | N4: 6.02 | O4: 46307 | Q4: -0.54 | R4: 0.34 | S4: -0.97 | T4: -1.04 | U4: -2.56 | V4: 14.12 | W4: 22.7 | X4: 18.44 | AC4: 9.48 | AD4: -3.74 | AE4: 47.2 | AF4: 0.43 | AG4: 10.54 | AH4: Golden (62d) | AI4: -1.01 | AJ4: -16.54 | AK4: 41.2 | AL4: 30.4 | AM4: 34.15 | AN4: 17.79 | AO4: 14.25 | AP4: 0.33 | AQ4: 0.96 | AR4: 300 | AS4: 46275 | AT4: 186328006656 | AU4: 186328006656 | AV4: 100 | AW4: 63634001920 | AX4: 55681000000 | AY4: 29.88 | AZ4: 183112040448 | BA4: 26.4 | BB4: 84.3 | BC4: =IF(AND(ISNUMBER(O4),ISNUMBER(AS4)),O4-AS4,"") -> 32 | BD4: =IF(OR(ISNUMBER(SEARCH("ETF",H4)),AND(F4="",AO4="")),1,0) -> 0 | BE4: =IF(ISNUMBER(L4),IF(L4>=Parameters!$B$3,2,IF(L4>=Parameters!$B$4,1,0)),0)+IF(ISNUMBER(AW4),IF(AW4>0,IF(AND(ISNUMBER(AM4),AM4>=Parameters!$B$5),2,1),0),0)+IF(ISNUMBER(AX4),IF(AND(AX4>0,ISNUMBER(AY4),AY4>=Parameters!$B$6),1,0),0)+IF(ISNUMBER(AO4),IF(AND(AO4>0,AO4<=Parameters!$B$7),1,0),0)+IF(ISNUMBER(F4),IF(F4>=Parameters!$B$8,1,0),0) -> 7 | BF4: =IF(BD4=1,"ETF",IF(OR(AND(ISNUMBER(L4),L4>=Parameters!$B$10),BE4>=Parameters!$B$9),"Established","Early")) -> Established | BG4: =IF(LEFT(AH4,6)="Golden",2,IF(LEFT(AH4,5)="Death",-2,0)) -> 2 | BH4: =IF(ISNUMBER(AG4),IF(AG4>Parameters!$B$12,2,IF(AG4>0,1,IF(AG4>=Parameters!$B$13,-1,-2))),0) -> 2 | BI4: =IF(ISNUMBER(AF4),IF(AND(AF4>=Parameters!$B$14,AF4<=Parameters!$B$15),1,IF(OR(AF4>Parameters!$B$16,AF4<Parameters!$B$17),-1,0)),0) -> 1 | BJ4: =IF(ISNUMBER(AE4),IF(AND(AE4>=Parameters!$B$18,AE4<=Parameters!$B$19),1,IF(OR(AE4>Parameters!$B$20,AE4<Parameters!$B$21),-1,0)),0) -> 1 | BK4: =IF(ISNUMBER(E4),IF(E4>Parameters!$B$22,1,IF(E4<Parameters!$B$23,-1,0)),0) -> 1 | BL4: =IF(ISNUMBER(C4),IF(C4>=Parameters!$B$24,1,IF(C4<=Parameters!$B$25,-1,0)),0) -> 1 | BM4: =IF(ISNUMBER(AJ4),IF(AND(AJ4>Parameters!$B$26,ISNUMBER(U4)),IF(U4<0,-1,1),0),0) -> 0 | BN4: =IF(ISNUMBER(AD4),IF(AD4>Parameters!$B$27,1,IF(AD4<Parameters!$B$28,-1,0)),0) -> 1 | BO4: =BG4+BH4+BI4+BJ4+BK4+BL4+BM4+BN4 -> 9 | BP4: =IF(ISNUMBER(F4),IF(F4>=Parameters!$B$30,2,IF(F4>=Parameters!$B$31,1,IF(F4<=Parameters!$B$32,-1,0))),0) -> 2 | BQ4: =IF(ISNUMBER(AK4),IF(AK4>Parameters!$B$33,1,IF(AK4<0,-1,0)),0) -> 1 | BR4: =IF(ISNUMBER(AL4),IF(AL4>Parameters!$B$34,1,IF(AL4<0,-1,0)),0) -> 1 | BS4: =IF(ISNUMBER(AP4),IF(AND(AP4>0,AP4<=Parameters!$B$35),1,IF(AP4>Parameters!$B$36,-1,0)),0) -> 1 | BT4: =IF(ISNUMBER(AY4),IF(AY4>Parameters!$B$37,1,IF(AY4<0,-1,0)),0) -> 1 | BU4: =IF(ISNUMBER(AZ4),IF(AZ4>0,1,0),0) -> 1 | BV4: =IF(ISNUMBER(AL4),IF(AL4>Parameters!$B$39,2,IF(AL4>Parameters!$B$40,1,IF(AL4<0,-2,IF(AL4<Parameters!$B$41,-1,0)))),0) -> 2 | BW4: =IF(ISNUMBER(AV4),IF(AV4>Parameters!$B$42,1,IF(AV4<Parameters!$B$43,-1,0)),0) -> 1 | BX4: =IF(AND(ISNUMBER(AX4),AX4>0),1,IF(AND(ISNUMBER(AY4),AY4<Parameters!$B$44),-1,0)) -> 1 | BY4: =IF(ISNUMBER(AW4),IF(AW4>0,1,0),0) -> 1 | BZ4: =IF(ISNUMBER(AQ4),IF(AQ4>Parameters!$B$46,-2,IF(AQ4>Parameters!$B$45,-1,0)),0) -> 0 | CA4: =IF(ISNUMBER(F4),IF(F4>=Parameters!$B$47,1,IF(F4<=Parameters!$B$48,-1,0)),0) -> 1 | CB4: =IF(BF4="Established",BP4+BQ4+BR4+BS4+BT4+BU4,IF(BF4="Early",BV4+BW4+BX4+BY4+BZ4+CA4,0)) -> 7 | CC4: =IF(BF4="Established",BO4+CB4,IF(BF4="Early",BO4+Parameters!$B$50*CB4,BO4)) -> 16 | CD4: =IF(BF4="Established",IF(CC4>=Parameters!$B$51,6,IF(CC4>=Parameters!$B$52,5,IF(CC4>=Parameters!$B$53,4,IF(CC4>=Parameters!$B$54,3,IF(CC4>=Parameters!$B$55,2,1))))),IF(BF4="Early",IF(CC4>=Parameters!$B$56,5,IF(CC4>=Parameters!$B$57,4,IF(CC4>=Parameters!$B$58,3,IF(CC4>=Parameters!$B$59,2,1)))),IF(CC4>=Parameters!$B$60,6,IF(CC4>=Parameters!$B$61,5,IF(CC4>=Parameters!$B$62,4,IF(CC4>=Parameters!$B$63,3,IF(CC4>=Parameters!$B$64,2,1))))))) -> 6 | CE4: =IF(AND(ISNUMBER(AR4),AR4<Parameters!$B$66),1,0) -> 0 | CF4: =IF(AND(LEFT(AH4,5)="Death",ISNUMBER(AG4)),IF(BF4="Early",IF(AND(AG4<Parameters!$B$70,ISNUMBER(U4),U4<Parameters!$B$71),1,0),IF(AND(AG4<Parameters!$B$67,OR(AND(ISNUMBER(U4),U4<Parameters!$B$68),AND(ISNUMBER(V4),V4<Parameters!$B$69))),1,0)),0) -> 0 | CG4: =IF(AND(ISNUMBER(AG4),AG4<0),1,0) -> 0 | CH4: =IF(OR(AND(ISNUMBER(U4),U4>Parameters!$B$74),AND(ISNUMBER(AF4),AF4>Parameters!$B$75),AND(ISNUMBER(AE4),AE4>Parameters!$B$76)),1,0) -> 0 | CI4: =IF(AND(ISNUMBER(BC4),BC4>=0,BC4<=Parameters!$B$77),1,0) -> 0 | CJ4: =IF(CF4=1,1,MIN(CD4,IF(CE4=1,3,6),IF(CG4=1,IF(BF4="Early",Parameters!$B$73,Parameters!$B$72),6),IF(CH4=1,3,6),IF(CI4=1,3,6))) -> 6 | CK4: =INDEX(Parameters!$F$2:$F$7,CJ4) -> Strong Buy | CL4: =IF(CF4=1,"Hard sell: breakdown; ","")&IF(CE4=1,"Insufficient history; ","")&IF(AND(CF4=0,CG4=1),"Below 200D; ","")&IF(CH4=1,"Extended - wait for pullback; ","")&IF(CI4=1,"Earnings within "&Parameters!$B$77&"d; ","")
A5: DELL | B5: 8 | C5: 8 | D5: 81.6 | E5: 0.5 | F5: 8 | G5: Dell Technologies Inc. Class C Common Stock | H5: Hardware | I5: 515.23 | J5: USD | K5: Technology | L5: 345847734587 | M5: 46266 | N5: 43.09 | O5: 46357 | P5: estimated | Q5: -3.74 | R5: 0.26 | S5: 4.68 | T5: 11.08 | U5: 16.84 | V5: 39.31 | W5: 249.61 | X5: 324.79 | AC5: 34.67 | AD5: -8.48 | AE5: 59.76 | AF5: 15.46 | AG5: 98.49 | AH5: Golden | AI5: 6.27 | AJ5: 10.66 | AK5: 255.1 | AL5: 57.7 | AM5: 7.53 | AN5: -240.32 | AO5: 18.38 | AP5: 0.11 | AQ5: 4.65 | AR5: 300 | AS5: 46275 | AT5: 151197007872 | AU5: 30076999680 | AV5: 19.89 | AW5: 11377999872 | AX5: 173500000 | AY5: 0.11 | AZ5: -22897000448 | BA5: 367.45 | BB5: 89.45 | BC5: =IF(AND(ISNUMBER(O5),ISNUMBER(AS5)),O5-AS5,"") -> 82 | BD5: =IF(OR(ISNUMBER(SEARCH("ETF",H5)),AND(F5="",AO5="")),1,0) -> 0 | BE5: =IF(ISNUMBER(L5),IF(L5>=Parameters!$B$3,2,IF(L5>=Parameters!$B$4,1,0)),0)+IF(ISNUMBER(AW5),IF(AW5>0,IF(AND(ISNUMBER(AM5),AM5>=Parameters!$B$5),2,1),0),0)+IF(ISNUMBER(AX5),IF(AND(AX5>0,ISNUMBER(AY5),AY5>=Parameters!$B$6),1,0),0)+IF(ISNUMBER(AO5),IF(AND(AO5>0,AO5<=Parameters!$B$7),1,0),0)+IF(ISNUMBER(F5),IF(F5>=Parameters!$B$8,1,0),0) -> 6 | BF5: =IF(BD5=1,"ETF",IF(OR(AND(ISNUMBER(L5),L5>=Parameters!$B$10),BE5>=Parameters!$B$9),"Established","Early")) -> Established | BG5: =IF(LEFT(AH5,6)="Golden",2,IF(LEFT(AH5,5)="Death",-2,0)) -> 2 | BH5: =IF(ISNUMBER(AG5),IF(AG5>Parameters!$B$12,2,IF(AG5>0,1,IF(AG5>=Parameters!$B$13,-1,-2))),0) -> 2 | BI5: =IF(ISNUMBER(AF5),IF(AND(AF5>=Parameters!$B$14,AF5<=Parameters!$B$15),1,IF(OR(AF5>Parameters!$B$16,AF5<Parameters!$B$17),-1,0)),0) -> -1 | BJ5: =IF(ISNUMBER(AE5),IF(AND(AE5>=Parameters!$B$18,AE5<=Parameters!$B$19),1,IF(OR(AE5>Parameters!$B$20,AE5<Parameters!$B$21),-1,0)),0) -> 1 | BK5: =IF(ISNUMBER(E5),IF(E5>Parameters!$B$22,1,IF(E5<Parameters!$B$23,-1,0)),0) -> 0 | BL5: =IF(ISNUMBER(C5),IF(C5>=Parameters!$B$24,1,IF(C5<=Parameters!$B$25,-1,0)),0) -> 1 | BM5: =IF(ISNUMBER(AJ5),IF(AND(AJ5>Parameters!$B$26,ISNUMBER(U5)),IF(U5<0,-1,1),0),0) -> 1 | BN5: =IF(ISNUMBER(AD5),IF(AD5>Parameters!$B$27,1,IF(AD5<Parameters!$B$28,-1,0)),0) -> 1 | BO5: =BG5+BH5+BI5+BJ5+BK5+BL5+BM5+BN5 -> 7 | BP5: =IF(ISNUMBER(F5),IF(F5>=Parameters!$B$30,2,IF(F5>=Parameters!$B$31,1,IF(F5<=Parameters!$B$32,-1,0))),0) -> 2 | BQ5: =IF(ISNUMBER(AK5),IF(AK5>Parameters!$B$33,1,IF(AK5<0,-1,0)),0) -> 1 | BR5: =IF(ISNUMBER(AL5),IF(AL5>Parameters!$B$34,1,IF(AL5<0,-1,0)),0) -> 1 | BS5: =IF(ISNUMBER(AP5),IF(AND(AP5>0,AP5<=Parameters!$B$35),1,IF(AP5>Parameters!$B$36,-1,0)),0) -> 1 | BT5: =IF(ISNUMBER(AY5),IF(AY5>Parameters!$B$37,1,IF(AY5<0,-1,0)),0) -> 0 | BU5: =IF(ISNUMBER(AZ5),IF(AZ5>0,1,0),0) -> 0 | BV5: =IF(ISNUMBER(AL5),IF(AL5>Parameters!$B$39,2,IF(AL5>Parameters!$B$40,1,IF(AL5<0,-2,IF(AL5<Parameters!$B$41,-1,0)))),0) -> 2 | BW5: =IF(ISNUMBER(AV5),IF(AV5>Parameters!$B$42,1,IF(AV5<Parameters!$B$43,-1,0)),0) -> -1 | BX5: =IF(AND(ISNUMBER(AX5),AX5>0),1,IF(AND(ISNUMBER(AY5),AY5<Parameters!$B$44),-1,0)) -> 1 | BY5: =IF(ISNUMBER(AW5),IF(AW5>0,1,0),0) -> 1 | BZ5: =IF(ISNUMBER(AQ5),IF(AQ5>Parameters!$B$46,-2,IF(AQ5>Parameters!$B$45,-1,0)),0) -> 0 | CA5: =IF(ISNUMBER(F5),IF(F5>=Parameters!$B$47,1,IF(F5<=Parameters!$B$48,-1,0)),0) -> 1 | CB5: =IF(BF5="Established",BP5+BQ5+BR5+BS5+BT5+BU5,IF(BF5="Early",BV5+BW5+BX5+BY5+BZ5+CA5,0)) -> 5 | CC5: =IF(BF5="Established",BO5+CB5,IF(BF5="Early",BO5+Parameters!$B$50*CB5,BO5)) -> 12 | CD5: =IF(BF5="Established",IF(CC5>=Parameters!$B$51,6,IF(CC5>=Parameters!$B$52,5,IF(CC5>=Parameters!$B$53,4,IF(CC5>=Parameters!$B$54,3,IF(CC5>=Parameters!$B$55,2,1))))),IF(BF5="Early",IF(CC5>=Parameters!$B$56,5,IF(CC5>=Parameters!$B$57,4,IF(CC5>=Parameters!$B$58,3,IF(CC5>=Parameters!$B$59,2,1)))),IF(CC5>=Parameters!$B$60,6,IF(CC5>=Parameters!$B$61,5,IF(CC5>=Parameters!$B$62,4,IF(CC5>=Parameters!$B$63,3,IF(CC5>=Parameters!$B$64,2,1))))))) -> 5 | CE5: =IF(AND(ISNUMBER(AR5),AR5<Parameters!$B$66),1,0) -> 0 | CF5: =IF(AND(LEFT(AH5,5)="Death",ISNUMBER(AG5)),IF(BF5="Early",IF(AND(AG5<Parameters!$B$70,ISNUMBER(U5),U5<Parameters!$B$71),1,0),IF(AND(AG5<Parameters!$B$67,OR(AND(ISNUMBER(U5),U5<Parameters!$B$68),AND(ISNUMBER(V5),V5<Parameters!$B$69))),1,0)),0) -> 0 | CG5: =IF(AND(ISNUMBER(AG5),AG5<0),1,0) -> 0 | CH5: =IF(OR(AND(ISNUMBER(U5),U5>Parameters!$B$74),AND(ISNUMBER(AF5),AF5>Parameters!$B$75),AND(ISNUMBER(AE5),AE5>Parameters!$B$76)),1,0) -> 1 | CI5: =IF(AND(ISNUMBER(BC5),BC5>=0,BC5<=Parameters!$B$77),1,0) -> 0 | CJ5: =IF(CF5=1,1,MIN(CD5,IF(CE5=1,3,6),IF(CG5=1,IF(BF5="Early",Parameters!$B$73,Parameters!$B$72),6),IF(CH5=1,3,6),IF(CI5=1,3,6))) -> 3 | CK5: =INDEX(Parameters!$F$2:$F$7,CJ5) -> Hold | CL5: =IF(CF5=1,"Hard sell: breakdown; ","")&IF(CE5=1,"Insufficient history; ","")&IF(AND(CF5=0,CG5=1),"Below 200D; ","")&IF(CH5=1,"Extended - wait for pullback; ","")&IF(CI5=1,"Earnings within "&Parameters!$B$77&"d; ","") -> Extended - wait for pullback;
A6: STX | B6: 8 | C6: 7 | D6: 66.6 | E6: 3.4 | F6: 10 | G6: Seagate Technology Holdings plc | H6: Memory | I6: 854.39 | J6: USD | K6: Technology | L6: 200788906853 | M6: 46231 | N6: 2.3 | O6: 46322 | P6: estimated | Q6: -3.56 | R6: -2.04 | S6: 5.67 | T6: 0.95 | U6: 4.13 | V6: 4.71 | W6: 121.36 | X6: 345.95 | AC6: 0.06 | AD6: -25.38 | AE6: 50.35 | AF6: 0.55 | AG6: 41.72 | AH6: Golden | AI6: 4.37 | AJ6: -17.35 | AK6: 165.2 | AL6: 48.5 | AM6: 26.11 | AN6: 371.53 | AO6: 16.04 | AP6: 0.43 | AQ6: 3.61 | AR6: 300 | AS6: 46275 | AT6: 12195000320 | AU6: 5558000128 | AV6: 45.58 | AW6: 3184000000 | AX6: 1943750016 | AY6: 15.94 | AZ6: -2193999872 | BA6: 349.92 | BB6: 69.57 | BC6: =IF(AND(ISNUMBER(O6),ISNUMBER(AS6)),O6-AS6,"") -> 47 | BD6: =IF(OR(ISNUMBER(SEARCH("ETF",H6)),AND(F6="",AO6="")),1,0) -> 0 | BE6: =IF(ISNUMBER(L6),IF(L6>=Parameters!$B$3,2,IF(L6>=Parameters!$B$4,1,0)),0)+IF(ISNUMBER(AW6),IF(AW6>0,IF(AND(ISNUMBER(AM6),AM6>=Parameters!$B$5),2,1),0),0)+IF(ISNUMBER(AX6),IF(AND(AX6>0,ISNUMBER(AY6),AY6>=Parameters!$B$6),1,0),0)+IF(ISNUMBER(AO6),IF(AND(AO6>0,AO6<=Parameters!$B$7),1,0),0)+IF(ISNUMBER(F6),IF(F6>=Parameters!$B$8,1,0),0) -> 7 | BF6: =IF(BD6=1,"ETF",IF(OR(AND(ISNUMBER(L6),L6>=Parameters!$B$10),BE6>=Parameters!$B$9),"Established","Early")) -> Established | BG6: =IF(LEFT(AH6,6)="Golden",2,IF(LEFT(AH6,5)="Death",-2,0)) -> 2 | BH6: =IF(ISNUMBER(AG6),IF(AG6>Parameters!$B$12,2,IF(AG6>0,1,IF(AG6>=Parameters!$B$13,-1,-2))),0) -> 2 | BI6: =IF(ISNUMBER(AF6),IF(AND(AF6>=Parameters!$B$14,AF6<=Parameters!$B$15),1,IF(OR(AF6>Parameters!$B$16,AF6<Parameters!$B$17),-1,0)),0) -> 1 | BJ6: =IF(ISNUMBER(AE6),IF(AND(AE6>=Parameters!$B$18,AE6<=Parameters!$B$19),1,IF(OR(AE6>Parameters!$B$20,AE6<Parameters!$B$21),-1,0)),0) -> 1 | BK6: =IF(ISNUMBER(E6),IF(E6>Parameters!$B$22,1,IF(E6<Parameters!$B$23,-1,0)),0) -> 1 | BL6: =IF(ISNUMBER(C6),IF(C6>=Parameters!$B$24,1,IF(C6<=Parameters!$B$25,-1,0)),0) -> 1 | BM6: =IF(ISNUMBER(AJ6),IF(AND(AJ6>Parameters!$B$26,ISNUMBER(U6)),IF(U6<0,-1,1),0),0) -> 0 | BN6: =IF(ISNUMBER(AD6),IF(AD6>Parameters!$B$27,1,IF(AD6<Parameters!$B$28,-1,0)),0) -> 0 | BO6: =BG6+BH6+BI6+BJ6+BK6+BL6+BM6+BN6 -> 8 | BP6: =IF(ISNUMBER(F6),IF(F6>=Parameters!$B$30,2,IF(F6>=Parameters!$B$31,1,IF(F6<=Parameters!$B$32,-1,0))),0) -> 2 | BQ6: =IF(ISNUMBER(AK6),IF(AK6>Parameters!$B$33,1,IF(AK6<0,-1,0)),0) -> 1 | BR6: =IF(ISNUMBER(AL6),IF(AL6>Parameters!$B$34,1,IF(AL6<0,-1,0)),0) -> 1 | BS6: =IF(ISNUMBER(AP6),IF(AND(AP6>0,AP6<=Parameters!$B$35),1,IF(AP6>Parameters!$B$36,-1,0)),0) -> 1 | BT6: =IF(ISNUMBER(AY6),IF(AY6>Parameters!$B$37,1,IF(AY6<0,-1,0)),0) -> 1 | BU6: =IF(ISNUMBER(AZ6),IF(AZ6>0,1,0),0) -> 0 | BV6: =IF(ISNUMBER(AL6),IF(AL6>Parameters!$B$39,2,IF(AL6>Parameters!$B$40,1,IF(AL6<0,-2,IF(AL6<Parameters!$B$41,-1,0)))),0) -> 2 | BW6: =IF(ISNUMBER(AV6),IF(AV6>Parameters!$B$42,1,IF(AV6<Parameters!$B$43,-1,0)),0) -> 0 | BX6: =IF(AND(ISNUMBER(AX6),AX6>0),1,IF(AND(ISNUMBER(AY6),AY6<Parameters!$B$44),-1,0)) -> 1 | BY6: =IF(ISNUMBER(AW6),IF(AW6>0,1,0),0) -> 1 | BZ6: =IF(ISNUMBER(AQ6),IF(AQ6>Parameters!$B$46,-2,IF(AQ6>Parameters!$B$45,-1,0)),0) -> 0 | CA6: =IF(ISNUMBER(F6),IF(F6>=Parameters!$B$47,1,IF(F6<=Parameters!$B$48,-1,0)),0) -> 1 | CB6: =IF(BF6="Established",BP6+BQ6+BR6+BS6+BT6+BU6,IF(BF6="Early",BV6+BW6+BX6+BY6+BZ6+CA6,0)) -> 6 | CC6: =IF(BF6="Established",BO6+CB6,IF(BF6="Early",BO6+Parameters!$B$50*CB6,BO6)) -> 14 | CD6: =IF(BF6="Established",IF(CC6>=Parameters!$B$51,6,IF(CC6>=Parameters!$B$52,5,IF(CC6>=Parameters!$B$53,4,IF(CC6>=Parameters!$B$54,3,IF(CC6>=Parameters!$B$55,2,1))))),IF(BF6="Early",IF(CC6>=Parameters!$B$56,5,IF(CC6>=Parameters!$B$57,4,IF(CC6>=Parameters!$B$58,3,IF(CC6>=Parameters!$B$59,2,1)))),IF(CC6>=Parameters!$B$60,6,IF(CC6>=Parameters!$B$61,5,IF(CC6>=Parameters!$B$62,4,IF(CC6>=Parameters!$B$63,3,IF(CC6>=Parameters!$B$64,2,1))))))) -> 6 | CE6: =IF(AND(ISNUMBER(AR6),AR6<Parameters!$B$66),1,0) -> 0 | CF6: =IF(AND(LEFT(AH6,5)="Death",ISNUMBER(AG6)),IF(BF6="Early",IF(AND(AG6<Parameters!$B$70,ISNUMBER(U6),U6<Parameters!$B$71),1,0),IF(AND(AG6<Parameters!$B$67,OR(AND(ISNUMBER(U6),U6<Parameters!$B$68),AND(ISNUMBER(V6),V6<Parameters!$B$69))),1,0)),0) -> 0 | CG6: =IF(AND(ISNUMBER(AG6),AG6<0),1,0) -> 0 | CH6: =IF(OR(AND(ISNUMBER(U6),U6>Parameters!$B$74),AND(ISNUMBER(AF6),AF6>Parameters!$B$75),AND(ISNUMBER(AE6),AE6>Parameters!$B$76)),1,0) -> 0 | CI6: =IF(AND(ISNUMBER(BC6),BC6>=0,BC6<=Parameters!$B$77),1,0) -> 0 | CJ6: =IF(CF6=1,1,MIN(CD6,IF(CE6=1,3,6),IF(CG6=1,IF(BF6="Early",Parameters!$B$73,Parameters!$B$72),6),IF(CH6=1,3,6),IF(CI6=1,3,6))) -> 6 | CK6: =INDEX(Parameters!$F$2:$F$7,CJ6) -> Strong Buy | CL6: =IF(CF6=1,"Hard sell: breakdown; ","")&IF(CE6=1,"Insufficient history; ","")&IF(AND(CF6=0,CG6=1),"Below 200D; ","")&IF(CH6=1,"Extended - wait for pullback; ","")&IF(CI6=1,"Earnings within "&Parameters!$B$77&"d; ","")
A7: TWLO | B7: 8 | C7: 8 | D7: 71 | E7: 5 | F7: 9 | G7: Twilio Inc. Class A Common Stock | H7: Software | I7: 233.16 | J7: USD | K7: Technology | L7: 34890754231 | M7: 46240 | N7: 11.36 | O7: 46331 | P7: estimated | Q7: 2.63 | R7: 0.58 | S7: 2.83 | T7: 2.06 | U7: -8.9 | V7: 12.59 | W7: 84.05 | X7: 117.91 | AC7: 7.95 | AD7: -9.75 | AE7: 54.36 | AF7: 7.28 | AG7: 41.42 | AH7: Golden | AI7: -1.23 | AJ7: -28.2 | AK7: 4659.4 | AL7: 22 | AM7: 20.62 | AN7: 13.5 | AO7: 32.82 | AP7: 0.01 | AQ7: 2.75 | AR7: 300 | AS7: 46275 | AT7: 5572327936 | AU7: 2706002944 | AV7: 48.56 | AW7: 1148742016 | AX7: 954675392 | AY7: 17.13 | AZ7: 1590811008 | BA7: 136.85 | BB7: 84.25 | BC7: =IF(AND(ISNUMBER(O7),ISNUMBER(AS7)),O7-AS7,"") -> 56 | BD7: =IF(OR(ISNUMBER(SEARCH("ETF",H7)),AND(F7="",AO7="")),1,0) -> 0 | BE7: =IF(ISNUMBER(L7),IF(L7>=Parameters!$B$3,2,IF(L7>=Parameters!$B$4,1,0)),0)+IF(ISNUMBER(AW7),IF(AW7>0,IF(AND(ISNUMBER(AM7),AM7>=Parameters!$B$5),2,1),0),0)+IF(ISNUMBER(AX7),IF(AND(AX7>0,ISNUMBER(AY7),AY7>=Parameters!$B$6),1,0),0)+IF(ISNUMBER(AO7),IF(AND(AO7>0,AO7<=Parameters!$B$7),1,0),0)+IF(ISNUMBER(F7),IF(F7>=Parameters!$B$8,1,0),0) -> 6 | BF7: =IF(BD7=1,"ETF",IF(OR(AND(ISNUMBER(L7),L7>=Parameters!$B$10),BE7>=Parameters!$B$9),"Established","Early")) -> Established | BG7: =IF(LEFT(AH7,6)="Golden",2,IF(LEFT(AH7,5)="Death",-2,0)) -> 2 | BH7: =IF(ISNUMBER(AG7),IF(AG7>Parameters!$B$12,2,IF(AG7>0,1,IF(AG7>=Parameters!$B$13,-1,-2))),0) -> 2 | BI7: =IF(ISNUMBER(AF7),IF(AND(AF7>=Parameters!$B$14,AF7<=Parameters!$B$15),1,IF(OR(AF7>Parameters!$B$16,AF7<Parameters!$B$17),-1,0)),0) -> 1 | BJ7: =IF(ISNUMBER(AE7),IF(AND(AE7>=Parameters!$B$18,AE7<=Parameters!$B$19),1,IF(OR(AE7>Parameters!$B$20,AE7<Parameters!$B$21),-1,0)),0) -> 1 | BK7: =IF(ISNUMBER(E7),IF(E7>Parameters!$B$22,1,IF(E7<Parameters!$B$23,-1,0)),0) -> 1 | BL7: =IF(ISNUMBER(C7),IF(C7>=Parameters!$B$24,1,IF(C7<=Parameters!$B$25,-1,0)),0) -> 1 | BM7: =IF(ISNUMBER(AJ7),IF(AND(AJ7>Parameters!$B$26,ISNUMBER(U7)),IF(U7<0,-1,1),0),0) -> 0 | BN7: =IF(ISNUMBER(AD7),IF(AD7>Parameters!$B$27,1,IF(AD7<Parameters!$B$28,-1,0)),0) -> 1 | BO7: =BG7+BH7+BI7+BJ7+BK7+BL7+BM7+BN7 -> 9 | BP7: =IF(ISNUMBER(F7),IF(F7>=Parameters!$B$30,2,IF(F7>=Parameters!$B$31,1,IF(F7<=Parameters!$B$32,-1,0))),0) -> 2 | BQ7: =IF(ISNUMBER(AK7),IF(AK7>Parameters!$B$33,1,IF(AK7<0,-1,0)),0) -> 1 | BR7: =IF(ISNUMBER(AL7),IF(AL7>Parameters!$B$34,1,IF(AL7<0,-1,0)),0) -> 1 | BS7: =IF(ISNUMBER(AP7),IF(AND(AP7>0,AP7<=Parameters!$B$35),1,IF(AP7>Parameters!$B$36,-1,0)),0) -> 1 | BT7: =IF(ISNUMBER(AY7),IF(AY7>Parameters!$B$37,1,IF(AY7<0,-1,0)),0) -> 1 | BU7: =IF(ISNUMBER(AZ7),IF(AZ7>0,1,0),0) -> 1 | BV7: =IF(ISNUMBER(AL7),IF(AL7>Parameters!$B$39,2,IF(AL7>Parameters!$B$40,1,IF(AL7<0,-2,IF(AL7<Parameters!$B$41,-1,0)))),0) -> 1 | BW7: =IF(ISNUMBER(AV7),IF(AV7>Parameters!$B$42,1,IF(AV7<Parameters!$B$43,-1,0)),0) -> 0 | BX7: =IF(AND(ISNUMBER(AX7),AX7>0),1,IF(AND(ISNUMBER(AY7),AY7<Parameters!$B$44),-1,0)) -> 1 | BY7: =IF(ISNUMBER(AW7),IF(AW7>0,1,0),0) -> 1 | BZ7: =IF(ISNUMBER(AQ7),IF(AQ7>Parameters!$B$46,-2,IF(AQ7>Parameters!$B$45,-1,0)),0) -> 0 | CA7: =IF(ISNUMBER(F7),IF(F7>=Parameters!$B$47,1,IF(F7<=Parameters!$B$48,-1,0)),0) -> 1 | CB7: =IF(BF7="Established",BP7+BQ7+BR7+BS7+BT7+BU7,IF(BF7="Early",BV7+BW7+BX7+BY7+BZ7+CA7,0)) -> 7 | CC7: =IF(BF7="Established",BO7+CB7,IF(BF7="Early",BO7+Parameters!$B$50*CB7,BO7)) -> 16 | CD7: =IF(BF7="Established",IF(CC7>=Parameters!$B$51,6,IF(CC7>=Parameters!$B$52,5,IF(CC7>=Parameters!$B$53,4,IF(CC7>=Parameters!$B$54,3,IF(CC7>=Parameters!$B$55,2,1))))),IF(BF7="Early",IF(CC7>=Parameters!$B$56,5,IF(CC7>=Parameters!$B$57,4,IF(CC7>=Parameters!$B$58,3,IF(CC7>=Parameters!$B$59,2,1)))),IF(CC7>=Parameters!$B$60,6,IF(CC7>=Parameters!$B$61,5,IF(CC7>=Parameters!$B$62,4,IF(CC7>=Parameters!$B$63,3,IF(CC7>=Parameters!$B$64,2,1))))))) -> 6 | CE7: =IF(AND(ISNUMBER(AR7),AR7<Parameters!$B$66),1,0) -> 0 | CF7: =IF(AND(LEFT(AH7,5)="Death",ISNUMBER(AG7)),IF(BF7="Early",IF(AND(AG7<Parameters!$B$70,ISNUMBER(U7),U7<Parameters!$B$71),1,0),IF(AND(AG7<Parameters!$B$67,OR(AND(ISNUMBER(U7),U7<Parameters!$B$68),AND(ISNUMBER(V7),V7<Parameters!$B$69))),1,0)),0) -> 0 | CG7: =IF(AND(ISNUMBER(AG7),AG7<0),1,0) -> 0 | CH7: =IF(OR(AND(ISNUMBER(U7),U7>Parameters!$B$74),AND(ISNUMBER(AF7),AF7>Parameters!$B$75),AND(ISNUMBER(AE7),AE7>Parameters!$B$76)),1,0) -> 0 | CI7: =IF(AND(ISNUMBER(BC7),BC7>=0,BC7<=Parameters!$B$77),1,0) -> 0 | CJ7: =IF(CF7=1,1,MIN(CD7,IF(CE7=1,3,6),IF(CG7=1,IF(BF7="Early",Parameters!$B$73,Parameters!$B$72),6),IF(CH7=1,3,6),IF(CI7=1,3,6))) -> 6 | CK7: =INDEX(Parameters!$F$2:$F$7,CJ7) -> Strong Buy | CL7: =IF(CF7=1,"Hard sell: breakdown; ","")&IF(CE7=1,"Insufficient history; ","")&IF(AND(CF7=0,CG7=1),"Below 200D; ","")&IF(CH7=1,"Extended - wait for pullback; ","")&IF(CI7=1,"Earnings within "&Parameters!$B$77&"d; ","")
A8: AMD | B8: 8 | C8: 7 | D8: 66.2 | E8: 5.7 | F8: 8 | G8: Advanced Micro Devices, Inc. | H8: Chips | I8: 505.95 | J8: USD | K8: Technology | L8: 850674534669 | M8: 46238 | N8: 3.11 | O8: 46329 | P8: estimated | Q8: -2.91 | R8: 3.04 | S8: 10.7 | T8: 5.2 | U8: 6.67 | V8: 11.84 | W8: 147.01 | X8: 224.7 | AC8: 7.2 | AD8: -13.47 | AE8: 55.75 | AF8: 1.78 | AG8: 46.5 | AH8: Golden | AI8: 5.94 | AJ8: -1.17 | AK8: 163.4 | AL8: 50.1 | AM8: 15.66 | AN8: 10.2 | AO8: 33.43 | AP8: 0.83 | AQ8: 2.47 | AR8: 300 | AS8: 46275 | AT8: 41305001984 | AU8: 23017000960 | AV8: 55.72 | AW8: 6469000192 | AX8: 8841499648 | AY8: 21.41 | AZ8: 8835000064 | BA8: 237.64 | BB8: 81.88 | BC8: =IF(AND(ISNUMBER(O8),ISNUMBER(AS8)),O8-AS8,"") -> 54 | BD8: =IF(OR(ISNUMBER(SEARCH("ETF",H8)),AND(F8="",AO8="")),1,0) -> 0 | BE8: =IF(ISNUMBER(L8),IF(L8>=Parameters!$B$3,2,IF(L8>=Parameters!$B$4,1,0)),0)+IF(ISNUMBER(AW8),IF(AW8>0,IF(AND(ISNUMBER(AM8),AM8>=Parameters!$B$5),2,1),0),0)+IF(ISNUMBER(AX8),IF(AND(AX8>0,ISNUMBER(AY8),AY8>=Parameters!$B$6),1,0),0)+IF(ISNUMBER(AO8),IF(AND(AO8>0,AO8<=Parameters!$B$7),1,0),0)+IF(ISNUMBER(F8),IF(F8>=Parameters!$B$8,1,0),0) -> 7 | BF8: =IF(BD8=1,"ETF",IF(OR(AND(ISNUMBER(L8),L8>=Parameters!$B$10),BE8>=Parameters!$B$9),"Established","Early")) -> Established | BG8: =IF(LEFT(AH8,6)="Golden",2,IF(LEFT(AH8,5)="Death",-2,0)) -> 2 | BH8: =IF(ISNUMBER(AG8),IF(AG8>Parameters!$B$12,2,IF(AG8>0,1,IF(AG8>=Parameters!$B$13,-1,-2))),0) -> 2 | BI8: =IF(ISNUMBER(AF8),IF(AND(AF8>=Parameters!$B$14,AF8<=Parameters!$B$15),1,IF(OR(AF8>Parameters!$B$16,AF8<Parameters!$B$17),-1,0)),0) -> 1 | BJ8: =IF(ISNUMBER(AE8),IF(AND(AE8>=Parameters!$B$18,AE8<=Parameters!$B$19),1,IF(OR(AE8>Parameters!$B$20,AE8<Parameters!$B$21),-1,0)),0) -> 1 | BK8: =IF(ISNUMBER(E8),IF(E8>Parameters!$B$22,1,IF(E8<Parameters!$B$23,-1,0)),0) -> 1 | BL8: =IF(ISNUMBER(C8),IF(C8>=Parameters!$B$24,1,IF(C8<=Parameters!$B$25,-1,0)),0) -> 1 | BM8: =IF(ISNUMBER(AJ8),IF(AND(AJ8>Parameters!$B$26,ISNUMBER(U8)),IF(U8<0,-1,1),0),0) -> 0 | BN8: =IF(ISNUMBER(AD8),IF(AD8>Parameters!$B$27,1,IF(AD8<Parameters!$B$28,-1,0)),0) -> 0 | BO8: =BG8+BH8+BI8+BJ8+BK8+BL8+BM8+BN8 -> 8 | BP8: =IF(ISNUMBER(F8),IF(F8>=Parameters!$B$30,2,IF(F8>=Parameters!$B$31,1,IF(F8<=Parameters!$B$32,-1,0))),0) -> 2 | BQ8: =IF(ISNUMBER(AK8),IF(AK8>Parameters!$B$33,1,IF(AK8<0,-1,0)),0) -> 1 | BR8: =IF(ISNUMBER(AL8),IF(AL8>Parameters!$B$34,1,IF(AL8<0,-1,0)),0) -> 1 | BS8: =IF(ISNUMBER(AP8),IF(AND(AP8>0,AP8<=Parameters!$B$35),1,IF(AP8>Parameters!$B$36,-1,0)),0) -> 1 | BT8: =IF(ISNUMBER(AY8),IF(AY8>Parameters!$B$37,1,IF(AY8<0,-1,0)),0) -> 1 | BU8: =IF(ISNUMBER(AZ8),IF(AZ8>0,1,0),0) -> 1 | BV8: =IF(ISNUMBER(AL8),IF(AL8>Parameters!$B$39,2,IF(AL8>Parameters!$B$40,1,IF(AL8<0,-2,IF(AL8<Parameters!$B$41,-1,0)))),0) -> 2 | BW8: =IF(ISNUMBER(AV8),IF(AV8>Parameters!$B$42,1,IF(AV8<Parameters!$B$43,-1,0)),0) -> 1 | BX8: =IF(AND(ISNUMBER(AX8),AX8>0),1,IF(AND(ISNUMBER(AY8),AY8<Parameters!$B$44),-1,0)) -> 1 | BY8: =IF(ISNUMBER(AW8),IF(AW8>0,1,0),0) -> 1 | BZ8: =IF(ISNUMBER(AQ8),IF(AQ8>Parameters!$B$46,-2,IF(AQ8>Parameters!$B$45,-1,0)),0) -> 0 | CA8: =IF(ISNUMBER(F8),IF(F8>=Parameters!$B$47,1,IF(F8<=Parameters!$B$48,-1,0)),0) -> 1 | CB8: =IF(BF8="Established",BP8+BQ8+BR8+BS8+BT8+BU8,IF(BF8="Early",BV8+BW8+BX8+BY8+BZ8+CA8,0)) -> 7 | CC8: =IF(BF8="Established",BO8+CB8,IF(BF8="Early",BO8+Parameters!$B$50*CB8,BO8)) -> 15 | CD8: =IF(BF8="Established",IF(CC8>=Parameters!$B$51,6,IF(CC8>=Parameters!$B$52,5,IF(CC8>=Parameters!$B$53,4,IF(CC8>=Parameters!$B$54,3,IF(CC8>=Parameters!$B$55,2,1))))),IF(BF8="Early",IF(CC8>=Parameters!$B$56,5,IF(CC8>=Parameters!$B$57,4,IF(CC8>=Parameters!$B$58,3,IF(CC8>=Parameters!$B$59,2,1)))),IF(CC8>=Parameters!$B$60,6,IF(CC8>=Parameters!$B$61,5,IF(CC8>=Parameters!$B$62,4,IF(CC8>=Parameters!$B$63,3,IF(CC8>=Parameters!$B$64,2,1))))))) -> 6 | CE8: =IF(AND(ISNUMBER(AR8),AR8<Parameters!$B$66),1,0) -> 0 | CF8: =IF(AND(LEFT(AH8,5)="Death",ISNUMBER(AG8)),IF(BF8="Early",IF(AND(AG8<Parameters!$B$70,ISNUMBER(U8),U8<Parameters!$B$71),1,0),IF(AND(AG8<Parameters!$B$67,OR(AND(ISNUMBER(U8),U8<Parameters!$B$68),AND(ISNUMBER(V8),V8<Parameters!$B$69))),1,0)),0) -> 0 | CG8: =IF(AND(ISNUMBER(AG8),AG8<0),1,0) -> 0 | CH8: =IF(OR(AND(ISNUMBER(U8),U8>Parameters!$B$74),AND(ISNUMBER(AF8),AF8>Parameters!$B$75),AND(ISNUMBER(AE8),AE8>Parameters!$B$76)),1,0) -> 0 | CI8: =IF(AND(ISNUMBER(BC8),BC8>=0,BC8<=Parameters!$B$77),1,0) -> 0 | CJ8: =IF(CF8=1,1,MIN(CD8,IF(CE8=1,3,6),IF(CG8=1,IF(BF8="Early",Parameters!$B$73,Parameters!$B$72),6),IF(CH8=1,3,6),IF(CI8=1,3,6))) -> 6 | CK8: =INDEX(Parameters!$F$2:$F$7,CJ8) -> Strong Buy | CL8: =IF(CF8=1,"Hard sell: breakdown; ","")&IF(CE8=1,"Insufficient history; ","")&IF(AND(CF8=0,CG8=1),"Below 200D; ","")&IF(CH8=1,"Extended - wait for pullback; ","")&IF(CI8=1,"Earnings within "&Parameters!$B$77&"d; ","")
A9: WDC | B9: 8 | C9: 7 | D9: 60.4 | E9: 0.7 | F9: 10 | G9: Western Digital Corp. | H9: Memory | I9: 459.51 | J9: USD | K9: Technology | L9: 173881686472 | M9: 46239 | N9: 7.88 | O9: 46330 | P9: estimated | Q9: -4.72 | R9: 1.04 | S9: 2.36 | T9: -2 | U9: 4.93 | V9: -6.24 | W9: 70.94 | X9: 386.05 | AC9: -10.88 | AD9: -42.55 | AE9: 46.45 | AF9: -7.7 | AG9: 21.67 | AH9: Golden | AI9: 4.07 | AJ9: -27.69 | AK9: 1033 | AL9: 43.8 | AM9: 71.88 | AN9: 130.85 | AO9: 14.91 | AP9: 0.02 | AQ9: 5.66 | AR9: 300 | AS9: 46275 | AT9: 12919000064 | AU9: 6311000064 | AV9: 48.85 | AW9: 9285999616 | AX9: 2268750080 | AY9: 17.56 | AZ9: 388000000 | BA9: 389.26 | BB9: 51.79 | BC9: =IF(AND(ISNUMBER(O9),ISNUMBER(AS9)),O9-AS9,"") -> 55 | BD9: =IF(OR(ISNUMBER(SEARCH("ETF",H9)),AND(F9="",AO9="")),1,0) -> 0 | BE9: =IF(ISNUMBER(L9),IF(L9>=Parameters!$B$3,2,IF(L9>=Parameters!$B$4,1,0)),0)+IF(ISNUMBER(AW9),IF(AW9>0,IF(AND(ISNUMBER(AM9),AM9>=Parameters!$B$5),2,1),0),0)+IF(ISNUMBER(AX9),IF(AND(AX9>0,ISNUMBER(AY9),AY9>=Parameters!$B$6),1,0),0)+IF(ISNUMBER(AO9),IF(AND(AO9>0,AO9<=Parameters!$B$7),1,0),0)+IF(ISNUMBER(F9),IF(F9>=Parameters!$B$8,1,0),0) -> 7 | BF9: =IF(BD9=1,"ETF",IF(OR(AND(ISNUMBER(L9),L9>=Parameters!$B$10),BE9>=Parameters!$B$9),"Established","Early")) -> Established | BG9: =IF(LEFT(AH9,6)="Golden",2,IF(LEFT(AH9,5)="Death",-2,0)) -> 2 | BH9: =IF(ISNUMBER(AG9),IF(AG9>Parameters!$B$12,2,IF(AG9>0,1,IF(AG9>=Parameters!$B$13,-1,-2))),0) -> 2 | BI9: =IF(ISNUMBER(AF9),IF(AND(AF9>=Parameters!$B$14,AF9<=Parameters!$B$15),1,IF(OR(AF9>Parameters!$B$16,AF9<Parameters!$B$17),-1,0)),0) -> 0 | BJ9: =IF(ISNUMBER(AE9),IF(AND(AE9>=Parameters!$B$18,AE9<=Parameters!$B$19),1,IF(OR(AE9>Parameters!$B$20,AE9<Parameters!$B$21),-1,0)),0) -> 1 | BK9: =IF(ISNUMBER(E9),IF(E9>Parameters!$B$22,1,IF(E9<Parameters!$B$23,-1,0)),0) -> 0 | BL9: =IF(ISNUMBER(C9),IF(C9>=Parameters!$B$24,1,IF(C9<=Parameters!$B$25,-1,0)),0) -> 1 | BM9: =IF(ISNUMBER(AJ9),IF(AND(AJ9>Parameters!$B$26,ISNUMBER(U9)),IF(U9<0,-1,1),0),0) -> 0 | BN9: =IF(ISNUMBER(AD9),IF(AD9>Parameters!$B$27,1,IF(AD9<Parameters!$B$28,-1,0)),0) -> -1 | BO9: =BG9+BH9+BI9+BJ9+BK9+BL9+BM9+BN9 -> 5 | BP9: =IF(ISNUMBER(F9),IF(F9>=Parameters!$B$30,2,IF(F9>=Parameters!$B$31,1,IF(F9<=Parameters!$B$32,-1,0))),0) -> 2 | BQ9: =IF(ISNUMBER(AK9),IF(AK9>Parameters!$B$33,1,IF(AK9<0,-1,0)),0) -> 1 | BR9: =IF(ISNUMBER(AL9),IF(AL9>Parameters!$B$34,1,IF(AL9<0,-1,0)),0) -> 1 | BS9: =IF(ISNUMBER(AP9),IF(AND(AP9>0,AP9<=Parameters!$B$35),1,IF(AP9>Parameters!$B$36,-1,0)),0) -> 1 | BT9: =IF(ISNUMBER(AY9),IF(AY9>Parameters!$B$37,1,IF(AY9<0,-1,0)),0) -> 1 | BU9: =IF(ISNUMBER(AZ9),IF(AZ9>0,1,0),0) -> 1 | BV9: =IF(ISNUMBER(AL9),IF(AL9>Parameters!$B$39,2,IF(AL9>Parameters!$B$40,1,IF(AL9<0,-2,IF(AL9<Parameters!$B$41,-1,0)))),0) -> 2 | BW9: =IF(ISNUMBER(AV9),IF(AV9>Parameters!$B$42,1,IF(AV9<Parameters!$B$43,-1,0)),0) -> 0 | BX9: =IF(AND(ISNUMBER(AX9),AX9>0),1,IF(AND(ISNUMBER(AY9),AY9<Parameters!$B$44),-1,0)) -> 1 | BY9: =IF(ISNUMBER(AW9),IF(AW9>0,1,0),0) -> 1 | BZ9: =IF(ISNUMBER(AQ9),IF(AQ9>Parameters!$B$46,-2,IF(AQ9>Parameters!$B$45,-1,0)),0) -> 0 | CA9: =IF(ISNUMBER(F9),IF(F9>=Parameters!$B$47,1,IF(F9<=Parameters!$B$48,-1,0)),0) -> 1 | CB9: =IF(BF9="Established",BP9+BQ9+BR9+BS9+BT9+BU9,IF(BF9="Early",BV9+BW9+BX9+BY9+BZ9+CA9,0)) -> 7 | CC9: =IF(BF9="Established",BO9+CB9,IF(BF9="Early",BO9+Parameters!$B$50*CB9,BO9)) -> 12 | CD9: =IF(BF9="Established",IF(CC9>=Parameters!$B$51,6,IF(CC9>=Parameters!$B$52,5,IF(CC9>=Parameters!$B$53,4,IF(CC9>=Parameters!$B$54,3,IF(CC9>=Parameters!$B$55,2,1))))),IF(BF9="Early",IF(CC9>=Parameters!$B$56,5,IF(CC9>=Parameters!$B$57,4,IF(CC9>=Parameters!$B$58,3,IF(CC9>=Parameters!$B$59,2,1)))),IF(CC9>=Parameters!$B$60,6,IF(CC9>=Parameters!$B$61,5,IF(CC9>=Parameters!$B$62,4,IF(CC9>=Parameters!$B$63,3,IF(CC9>=Parameters!$B$64,2,1))))))) -> 5 | CE9: =IF(AND(ISNUMBER(AR9),AR9<Parameters!$B$66),1,0) -> 0 | CF9: =IF(AND(LEFT(AH9,5)="Death",ISNUMBER(AG9)),IF(BF9="Early",IF(AND(AG9<Parameters!$B$70,ISNUMBER(U9),U9<Parameters!$B$71),1,0),IF(AND(AG9<Parameters!$B$67,OR(AND(ISNUMBER(U9),U9<Parameters!$B$68),AND(ISNUMBER(V9),V9<Parameters!$B$69))),1,0)),0) -> 0 | CG9: =IF(AND(ISNUMBER(AG9),AG9<0),1,0) -> 0 | CH9: =IF(OR(AND(ISNUMBER(U9),U9>Parameters!$B$74),AND(ISNUMBER(AF9),AF9>Parameters!$B$75),AND(ISNUMBER(AE9),AE9>Parameters!$B$76)),1,0) -> 0 | CI9: =IF(AND(ISNUMBER(BC9),BC9>=0,BC9<=Parameters!$B$77),1,0) -> 0 | CJ9: =IF(CF9=1,1,MIN(CD9,IF(CE9=1,3,6),IF(CG9=1,IF(BF9="Early",Parameters!$B$73,Parameters!$B$72),6),IF(CH9=1,3,6),IF(CI9=1,3,6))) -> 5 | CK9: =INDEX(Parameters!$F$2:$F$7,CJ9) -> Buy | CL9: =IF(CF9=1,"Hard sell: breakdown; ","")&IF(CE9=1,"Insufficient history; ","")&IF(AND(CF9=0,CG9=1),"Below 200D; ","")&IF(CH9=1,"Extended - wait for pullback; ","")&IF(CI9=1,"Earnings within "&Parameters!$B$77&"d; ","")
A10: SNDK | B10: 8 | C10: 7 | D10: 64.4 | E10: 4 | F10: 9 | G10: SanDisk Corporation | H10: Memory | I10: 1688.55 | J10: USD | K10: Technology | L10: 258308014850 | M10: 46239 | N10: 13.7 | O10: 46330 | P10: estimated | Q10: -4.29 | R10: 1.51 | S10: 8.7 | T10: 12.62 | U10: 32.85 | V10: 2.76 | W10: 157.62 | X10: 2294.77 | AC10: -1.88 | AD10: -28.28 | AE10: 57.08 | AF10: 10.67 | AG10: 64.5 | AH10: Golden | AI10: 24.58 | AJ10: -27.43 | AK10: 371.59 | AL10: 371.6 | AM10: 56.46 | AN10: 91.64 | AO10: 6.79 | AP10: 0 | AQ10: 5.32 | AR10: 300 | AS10: 46275 | AT10: 20248000512 | AU10: 14471999488 | AV10: 71.47 | AW10: 11432999936 | AX10: 7720875008 | AY10: 38.13 | AZ10: 4560999872 | BA10: 2244.23 | BB10: 70.83 | BC10: =IF(AND(ISNUMBER(O10),ISNUMBER(AS10)),O10-AS10,"") -> 55 | BD10: =IF(OR(ISNUMBER(SEARCH("ETF",H10)),AND(F10="",AO10="")),1,0) -> 0 | BE10: =IF(ISNUMBER(L10),IF(L10>=Parameters!$B$3,2,IF(L10>=Parameters!$B$4,1,0)),0)+IF(ISNUMBER(AW10),IF(AW10>0,IF(AND(ISNUMBER(AM10),AM10>=Parameters!$B$5),2,1),0),0)+IF(ISNUMBER(AX10),IF(AND(AX10>0,ISNUMBER(AY10),AY10>=Parameters!$B$6),1,0),0)+IF(ISNUMBER(AO10),IF(AND(AO10>0,AO10<=Parameters!$B$7),1,0),0)+IF(ISNUMBER(F10),IF(F10>=Parameters!$B$8,1,0),0) -> 7 | BF10: =IF(BD10=1,"ETF",IF(OR(AND(ISNUMBER(L10),L10>=Parameters!$B$10),BE10>=Parameters!$B$9),"Established","Early")) -> Established | BG10: =IF(LEFT(AH10,6)="Golden",2,IF(LEFT(AH10,5)="Death",-2,0)) -> 2 | BH10: =IF(ISNUMBER(AG10),IF(AG10>Parameters!$B$12,2,IF(AG10>0,1,IF(AG10>=Parameters!$B$13,-1,-2))),0) -> 2 | BI10: =IF(ISNUMBER(AF10),IF(AND(AF10>=Parameters!$B$14,AF10<=Parameters!$B$15),1,IF(OR(AF10>Parameters!$B$16,AF10<Parameters!$B$17),-1,0)),0) -> 0 | BJ10: =IF(ISNUMBER(AE10),IF(AND(AE10>=Parameters!$B$18,AE10<=Parameters!$B$19),1,IF(OR(AE10>Parameters!$B$20,AE10<Parameters!$B$21),-1,0)),0) -> 1 | BK10: =IF(ISNUMBER(E10),IF(E10>Parameters!$B$22,1,IF(E10<Parameters!$B$23,-1,0)),0) -> 1 | BL10: =IF(ISNUMBER(C10),IF(C10>=Parameters!$B$24,1,IF(C10<=Parameters!$B$25,-1,0)),0) -> 1 | BM10: =IF(ISNUMBER(AJ10),IF(AND(AJ10>Parameters!$B$26,ISNUMBER(U10)),IF(U10<0,-1,1),0),0) -> 0 | BN10: =IF(ISNUMBER(AD10),IF(AD10>Parameters!$B$27,1,IF(AD10<Parameters!$B$28,-1,0)),0) -> 0 | BO10: =BG10+BH10+BI10+BJ10+BK10+BL10+BM10+BN10 -> 7 | BP10: =IF(ISNUMBER(F10),IF(F10>=Parameters!$B$30,2,IF(F10>=Parameters!$B$31,1,IF(F10<=Parameters!$B$32,-1,0))),0) -> 2 | BQ10: =IF(ISNUMBER(AK10),IF(AK10>Parameters!$B$33,1,IF(AK10<0,-1,0)),0) -> 1 | BR10: =IF(ISNUMBER(AL10),IF(AL10>Parameters!$B$34,1,IF(AL10<0,-1,0)),0) -> 1 | BS10: =IF(ISNUMBER(AP10),IF(AND(AP10>0,AP10<=Parameters!$B$35),1,IF(AP10>Parameters!$B$36,-1,0)),0) -> 0 | BT10: =IF(ISNUMBER(AY10),IF(AY10>Parameters!$B$37,1,IF(AY10<0,-1,0)),0) -> 1 | BU10: =IF(ISNUMBER(AZ10),IF(AZ10>0,1,0),0) -> 1 | BV10: =IF(ISNUMBER(AL10),IF(AL10>Parameters!$B$39,2,IF(AL10>Parameters!$B$40,1,IF(AL10<0,-2,IF(AL10<Parameters!$B$41,-1,0)))),0) -> 2 | BW10: =IF(ISNUMBER(AV10),IF(AV10>Parameters!$B$42,1,IF(AV10<Parameters!$B$43,-1,0)),0) -> 1 | BX10: =IF(AND(ISNUMBER(AX10),AX10>0),1,IF(AND(ISNUMBER(AY10),AY10<Parameters!$B$44),-1,0)) -> 1 | BY10: =IF(ISNUMBER(AW10),IF(AW10>0,1,0),0) -> 1 | BZ10: =IF(ISNUMBER(AQ10),IF(AQ10>Parameters!$B$46,-2,IF(AQ10>Parameters!$B$45,-1,0)),0) -> 0 | CA10: =IF(ISNUMBER(F10),IF(F10>=Parameters!$B$47,1,IF(F10<=Parameters!$B$48,-1,0)),0) -> 1 | CB10: =IF(BF10="Established",BP10+BQ10+BR10+BS10+BT10+BU10,IF(BF10="Early",BV10+BW10+BX10+BY10+BZ10+CA10,0)) -> 6 | CC10: =IF(BF10="Established",BO10+CB10,IF(BF10="Early",BO10+Parameters!$B$50*CB10,BO10)) -> 13 | CD10: =IF(BF10="Established",IF(CC10>=Parameters!$B$51,6,IF(CC10>=Parameters!$B$52,5,IF(CC10>=Parameters!$B$53,4,IF(CC10>=Parameters!$B$54,3,IF(CC10>=Parameters!$B$55,2,1))))),IF(BF10="Early",IF(CC10>=Parameters!$B$56,5,IF(CC10>=Parameters!$B$57,4,IF(CC10>=Parameters!$B$58,3,IF(CC10>=Parameters!$B$59,2,1)))),IF(CC10>=Parameters!$B$60,6,IF(CC10>=Parameters!$B$61,5,IF(CC10>=Parameters!$B$62,4,IF(CC10>=Parameters!$B$63,3,IF(CC10>=Parameters!$B$64,2,1))))))) -> 6 | CE10: =IF(AND(ISNUMBER(AR10),AR10<Parameters!$B$66),1,0) -> 0 | CF10: =IF(AND(LEFT(AH10,5)="Death",ISNUMBER(AG10)),IF(BF10="Early",IF(AND(AG10<Parameters!$B$70,ISNUMBER(U10),U10<Parameters!$B$71),1,0),IF(AND(AG10<Parameters!$B$67,OR(AND(ISNUMBER(U10),U10<Parameters!$B$68),AND(ISNUMBER(V10),V10<Parameters!$B$69))),1,0)),0) -> 0 | CG10: =IF(AND(ISNUMBER(AG10),AG10<0),1,0) -> 0 | CH10: =IF(OR(AND(ISNUMBER(U10),U10>Parameters!$B$74),AND(ISNUMBER(AF10),AF10>Parameters!$B$75),AND(ISNUMBER(AE10),AE10>Parameters!$B$76)),1,0) -> 1 | CI10: =IF(AND(ISNUMBER(BC10),BC10>=0,BC10<=Parameters!$B$77),1,0) -> 0 | CJ10: =IF(CF10=1,1,MIN(CD10,IF(CE10=1,3,6),IF(CG10=1,IF(BF10="Early",Parameters!$B$73,Parameters!$B$72),6),IF(CH10=1,3,6),IF(CI10=1,3,6))) -> 3 | CK10: =INDEX(Parameters!$F$2:$F$7,CJ10) -> Hold | CL10: =IF(CF10=1,"Hard sell: breakdown; ","")&IF(CE10=1,"Insufficient history; ","")&IF(AND(CF10=0,CG10=1),"Below 200D; ","")&IF(CH10=1,"Extended - wait for pullback; ","")&IF(CI10=1,"Earnings within "&Parameters!$B$77&"d; ","") -> Extended - wait for pullback;
A11: TSM | B11: 8 | C11: 6 | D11: 50.6 | E11: 9.7 | F11: 10 | G11: Taiwan Semiconductor Manufacturing Company Ltd. ADR | H11: Chips | I11: 430.67 | J11: USD | K11: Technology | L11: 2257983274434 | M11: 46219 | N11: 10.8 | O11: 46310 | P11: estimated | Q11: -1.08 | R11: -0.83 | S11: 3.65 | T11: 3.11 | U11: 2.04 | V11: 5.36 | W11: 21.47 | X11: 71.64 | AC11: 0.72 | AD11: -10.09 | AE11: 55.79 | AF11: 2.73 | AG11: 14.79 | AH11: Golden | AI11: 1.91 | AJ11: -6.08 | AK11: 77.4 | AL11: 36 | AM11: 49.92 | AN11: 39.97 | AO11: 19.77 | AP11: 0.41 | AQ11: 0.08 | AR11: 300 | AS11: 46275 | AT11: 140865738606 | AU11: 90478306998 | AV11: 64.23 | AW11: 70323813356 | AX11: 23183993664 | AY11: 16.46 | AZ11: 77703956676 | BA11: 67.09 | BB11: 78.16 | BC11: =IF(AND(ISNUMBER(O11),ISNUMBER(AS11)),O11-AS11,"") -> 35 | BD11: =IF(OR(ISNUMBER(SEARCH("ETF",H11)),AND(F11="",AO11="")),1,0) -> 0 | BE11: =IF(ISNUMBER(L11),IF(L11>=Parameters!$B$3,2,IF(L11>=Parameters!$B$4,1,0)),0)+IF(ISNUMBER(AW11),IF(AW11>0,IF(AND(ISNUMBER(AM11),AM11>=Parameters!$B$5),2,1),0),0)+IF(ISNUMBER(AX11),IF(AND(AX11>0,ISNUMBER(AY11),AY11>=Parameters!$B$6),1,0),0)+IF(ISNUMBER(AO11),IF(AND(AO11>0,AO11<=Parameters!$B$7),1,0),0)+IF(ISNUMBER(F11),IF(F11>=Parameters!$B$8,1,0),0) -> 7 | BF11: =IF(BD11=1,"ETF",IF(OR(AND(ISNUMBER(L11),L11>=Parameters!$B$10),BE11>=Parameters!$B$9),"Established","Early")) -> Established | BG11: =IF(LEFT(AH11,6)="Golden",2,IF(LEFT(AH11,5)="Death",-2,0)) -> 2 | BH11: =IF(ISNUMBER(AG11),IF(AG11>Parameters!$B$12,2,IF(AG11>0,1,IF(AG11>=Parameters!$B$13,-1,-2))),0) -> 2 | BI11: =IF(ISNUMBER(AF11),IF(AND(AF11>=Parameters!$B$14,AF11<=Parameters!$B$15),1,IF(OR(AF11>Parameters!$B$16,AF11<Parameters!$B$17),-1,0)),0) -> 1 | BJ11: =IF(ISNUMBER(AE11),IF(AND(AE11>=Parameters!$B$18,AE11<=Parameters!$B$19),1,IF(OR(AE11>Parameters!$B$20,AE11<Parameters!$B$21),-1,0)),0) -> 1 | BK11: =IF(ISNUMBER(E11),IF(E11>Parameters!$B$22,1,IF(E11<Parameters!$B$23,-1,0)),0) -> 1 | BL11: =IF(ISNUMBER(C11),IF(C11>=Parameters!$B$24,1,IF(C11<=Parameters!$B$25,-1,0)),0) -> 0 | BM11: =IF(ISNUMBER(AJ11),IF(AND(AJ11>Parameters!$B$26,ISNUMBER(U11)),IF(U11<0,-1,1),0),0) -> 0 | BN11: =IF(ISNUMBER(AD11),IF(AD11>Parameters!$B$27,1,IF(AD11<Parameters!$B$28,-1,0)),0) -> 0 | BO11: =BG11+BH11+BI11+BJ11+BK11+BL11+BM11+BN11 -> 7 | BP11: =IF(ISNUMBER(F11),IF(F11>=Parameters!$B$30,2,IF(F11>=Parameters!$B$31,1,IF(F11<=Parameters!$B$32,-1,0))),0) -> 2 | BQ11: =IF(ISNUMBER(AK11),IF(AK11>Parameters!$B$33,1,IF(AK11<0,-1,0)),0) -> 1 | BR11: =IF(ISNUMBER(AL11),IF(AL11>Parameters!$B$34,1,IF(AL11<0,-1,0)),0) -> 1 | BS11: =IF(ISNUMBER(AP11),IF(AND(AP11>0,AP11<=Parameters!$B$35),1,IF(AP11>Parameters!$B$36,-1,0)),0) -> 1 | BT11: =IF(ISNUMBER(AY11),IF(AY11>Parameters!$B$37,1,IF(AY11<0,-1,0)),0) -> 1 | BU11: =IF(ISNUMBER(AZ11),IF(AZ11>0,1,0),0) -> 1 | BV11: =IF(ISNUMBER(AL11),IF(AL11>Parameters!$B$39,2,IF(AL11>Parameters!$B$40,1,IF(AL11<0,-2,IF(AL11<Parameters!$B$41,-1,0)))),0) -> 2 | BW11: =IF(ISNUMBER(AV11),IF(AV11>Parameters!$B$42,1,IF(AV11<Parameters!$B$43,-1,0)),0) -> 1 | BX11: =IF(AND(ISNUMBER(AX11),AX11>0),1,IF(AND(ISNUMBER(AY11),AY11<Parameters!$B$44),-1,0)) -> 1 | BY11: =IF(ISNUMBER(AW11),IF(AW11>0,1,0),0) -> 1 | BZ11: =IF(ISNUMBER(AQ11),IF(AQ11>Parameters!$B$46,-2,IF(AQ11>Parameters!$B$45,-1,0)),0) -> 0 | CA11: =IF(ISNUMBER(F11),IF(F11>=Parameters!$B$47,1,IF(F11<=Parameters!$B$48,-1,0)),0) -> 1 | CB11: =IF(BF11="Established",BP11+BQ11+BR11+BS11+BT11+BU11,IF(BF11="Early",BV11+BW11+BX11+BY11+BZ11+CA11,0)) -> 7 | CC11: =IF(BF11="Established",BO11+CB11,IF(BF11="Early",BO11+Parameters!$B$50*CB11,BO11)) -> 14 | CD11: =IF(BF11="Established",IF(CC11>=Parameters!$B$51,6,IF(CC11>=Parameters!$B$52,5,IF(CC11>=Parameters!$B$53,4,IF(CC11>=Parameters!$B$54,3,IF(CC11>=Parameters!$B$55,2,1))))),IF(BF11="Early",IF(CC11>=Parameters!$B$56,5,IF(CC11>=Parameters!$B$57,4,IF(CC11>=Parameters!$B$58,3,IF(CC11>=Parameters!$B$59,2,1)))),IF(CC11>=Parameters!$B$60,6,IF(CC11>=Parameters!$B$61,5,IF(CC11>=Parameters!$B$62,4,IF(CC11>=Parameters!$B$63,3,IF(CC11>=Parameters!$B$64,2,1))))))) -> 6 | CE11: =IF(AND(ISNUMBER(AR11),AR11<Parameters!$B$66),1,0) -> 0 | CF11: =IF(AND(LEFT(AH11,5)="Death",ISNUMBER(AG11)),IF(BF11="Early",IF(AND(AG11<Parameters!$B$70,ISNUMBER(U11),U11<Parameters!$B$71),1,0),IF(AND(AG11<Parameters!$B$67,OR(AND(ISNUMBER(U11),U11<Parameters!$B$68),AND(ISNUMBER(V11),V11<Parameters!$B$69))),1,0)),0) -> 0 | CG11: =IF(AND(ISNUMBER(AG11),AG11<0),1,0) -> 0 | CH11: =IF(OR(AND(ISNUMBER(U11),U11>Parameters!$B$74),AND(ISNUMBER(AF11),AF11>Parameters!$B$75),AND(ISNUMBER(AE11),AE11>Parameters!$B$76)),1,0) -> 0 | CI11: =IF(AND(ISNUMBER(BC11),BC11>=0,BC11<=Parameters!$B$77),1,0) -> 0 | CJ11: =IF(CF11=1,1,MIN(CD11,IF(CE11=1,3,6),IF(CG11=1,IF(BF11="Early",Parameters!$B$73,Parameters!$B$72),6),IF(CH11=1,3,6),IF(CI11=1,3,6))) -> 6 | CK11: =INDEX(Parameters!$F$2:$F$7,CJ11) -> Strong Buy | CL11: =IF(CF11=1,"Hard sell: breakdown; ","")&IF(CE11=1,"Insufficient history; ","")&IF(AND(CF11=0,CG11=1),"Below 200D; ","")&IF(CH11=1,"Extended - wait for pullback; ","")&IF(CI11=1,"Earnings within "&Parameters!$B$77&"d; ","")
